<!-- ## How to Write Tests -->

## テストの記述法

<!-- Tests are Rust functions that verify that the non-test code is functioning in -->
<!-- the expected manner. The bodies of test functions typically perform these three -->
<!-- actions: -->

テストは、非テストコードが想定された方法で機能していることを実証するRustの関数です。
テスト関数の本体は、典型的には以下の3つの動作を行います:

<!-- 1. Set up any needed data or state. -->
<!-- 2. Run the code we want to test. -->
<!-- 3. Assert the results are what we expect. -->

1. 必要なデータや状態をセットアップする。
2. テスト対象のコードを走らせる。
3. 結果が想定通りかアサーションする。

<!-- Let’s look at the features Rust provides specifically for writing tests that -->
<!-- take these actions, which include the `test` attribute, a few macros, and the -->
<!-- `should_panic` attribute. -->

Rustが、特にこれらの動作を行うテストを書くために用意している機能を見ていきましょう。
これには、`test`属性、いくつかのマクロ、`should_panic`属性が含まれます。

<!-- ### The Anatomy of a Test Function -->

## テスト関数の解剖

<!-- At its simplest, a test in Rust is a function that’s annotated with the `test` -->
<!-- attribute. Attributes are metadata about pieces of Rust code; one example is -->
<!-- the `derive` attribute we used with structs in Chapter 5. To change a function -->
<!-- into a test function, we add `#[test]` on the line before `fn`. When we run our -->
<!-- tests with the `cargo test` command, Rust builds a test runner binary that runs -->
<!-- the functions annotated with the `test` attribute and reports on whether each -->
<!-- test function passes or fails. -->

最も単純には、Rustにおけるテストは`test`属性で注釈された関数のことです。属性とは、
Rustコードの欠片に関するメタデータです; 一例を挙げれば、構造体とともに第5章で使用した`derive`属性です。
関数をテスト関数に変えるには、`fn`の前に`#[test]`を付け加えるのです。
`cargo test`コマンドでテストを実行したら、コンパイラは`test`属性で注釈された関数を走らせるテスト用バイナリをビルドし、
各テスト関数が通過したか失敗したかを報告します。

<!-- In Chapter 7, we saw that when we make a new library project with Cargo, a test -->
<!-- module with a test function in it is automatically generated for us. This -->
<!-- module helps us start writing our tests so you don’t have to look up the -->
<!-- exact structure and syntax of test functions every time you start a new -->
<!-- project. You can add as many additional test functions and as many test modules -->
<!-- as you want! -->

第7章で、Cargoで新規ライブラリプロジェクトを作成した時に、テスト関数が含まれるテストモジュールが自動で生成されたことを見かけました。
このモジュールのおかげでテストを書き始めることができるので、新しいプロジェクトを立ち上げる度に、
テスト関数の正確な構造と記法を調べる必要がなくなるわけです。必要なだけ追加のテスト関数とテストモジュールは追記することができます。

<!-- We’ll explore some aspects of how tests work by experimenting with the template -->
<!-- test generated for us without actually testing any code. Then we’ll write some -->
<!-- real-world tests that call some code that we’ve written and assert that its -->
<!-- behavior is correct. -->

実際にテストすることなしにテンプレートのテストが生成されるのを実験することでテストの動作法の一部の側面を探究しましょう。
それから、自分で書いた何らかのコードを呼び出し、振る舞いが正しいかアサーションする現実世界のテストを書きましょう。

<!-- Let’s create a new library project called `adder`: -->

`adder`という新しいライブラリプロジェクトを生成しましょう:

```text
$ cargo new adder --lib
     Created library `adder` project
$ cd adder
```

<!-- The contents of the *src/lib.rs* file in your `adder` library should look like -->
<!-- Listing 11-1. -->

`adder`ライブラリの*src/lib.rs*ファイルの中身は、リスト11-1のような見た目のはずです。

<!-- <span class="filename">Filename: src/lib.rs</span> -->

<span class="filename">ファイル名: src/lib.rs</span>

```rust
# fn main() {}
#[cfg(test)]
mod tests {
    #[test]
    fn it_works() {
        assert_eq!(2 + 2, 4);
    }
}
```

<!-- <span class="caption">Listing 11-1: The test module and function generated -->
<!-- automatically by `cargo new`</span> -->

<span class="caption">リスト11-1: `cargo new`で自動生成されたテストモジュールと関数</span>

<!-- For now, let’s ignore the top two lines and focus on the function to see how it -->
<!-- works. Note the `#[test]` annotation before the `fn` line: this attribute -->
<!-- indicates this is a test function, so the test runner knows to treat this -->
<!-- function as a test. We could also have non-test functions in the `tests` module -->
<!-- to help set up common scenarios or perform common operations, so we need to -->
<!-- indicate which functions are tests by using the `#[test]` attribute. -->

とりあえず、最初の2行は無視し、関数に集中してその動作法を見ましょう。
`fn`行の`#[test]`注釈に注目してください: この属性は、これがテスト関数であることを示唆しますので、
テスト実行機はこの関数をテストとして扱うとわかるのです。さらに、`tests`モジュール内には非テスト関数を入れ込み、
一般的なシナリオをセットアップしたり、共通の処理を行う手助けをしたりもできるので、
`#[test]`属性でどの関数がテストかを示唆する必要があるのです。

<!-- The function body uses the `assert_eq!` macro to assert that 2 + 2 equals 4. -->
<!-- This assertion serves as an example of the format for a typical test. Let’s run -->
<!-- it to see that this test passes. -->

関数本体は、`assert_eq!`マクロを使用して、2 + 2が4に等しいことをアサーションしています。
このアサーションは、典型的なテストのフォーマット例をなしているわけです。走らせてこのテストが通ることを確かめましょう。

<!-- The `cargo test` command runs all tests in our project, as shown in Listing -->
<!-- 11-2. -->

`cargo test`コマンドでプロジェクトにあるテストが全て実行されます。リスト11-2に示したようにですね。

```text
$ cargo test
   Compiling adder v0.1.0 (file:///projects/adder)
    Finished dev [unoptimized + debuginfo] target(s) in 0.22 secs
     Running target/debug/deps/adder-ce99bcc2479f4607

running 1 test
test tests::it_works ... ok

test result: ok. 1 passed; 0 failed; 0 ignored; 0 measured; 0 filtered out

   Doc-tests adder

running 0 tests

test result: ok. 0 passed; 0 failed; 0 ignored; 0 measured; 0 filtered out
```

<!-- <span class="caption">Listing 11-2: The output from running the automatically -->
<!-- generated test</span> -->

<span class="caption">リスト11-2: 自動生成されたテストを走らせた出力</span>

<!-- Cargo compiled and ran the test. After the `Compiling`, `Finished`, and -->
<!-- `Running` lines is the line `running 1 test`. The next line shows the name -->
<!-- of the generated test function, called `it_works`, and the result of running -->
<!-- that test, `ok`. The overall summary of running the tests appears next. The -->
<!-- text `test result: ok.` means that all the tests passed, and the portion that -->
<!-- reads `1 passed; 0 failed` totals the number of tests that passed or failed. -->

Cargoがテストをコンパイルし、走らせました。`Compiling`, `Finished`, `Running`の行の後に`running 1 test`の行があります。
次行が、生成されたテスト関数の`it_works`という名前とこのテストの実行結果、`ok`を示しています。
テスト実行の総合的なまとめが次に出現します。`test result:ok.`というテキストは、
全テストが通ったことを意味し、`1 passed; 0 failed`と読める部分は、通過または失敗したテストの数を合計しているのです。

<!-- Because we don’t have any tests we’ve marked as ignored, the summary shows `0 -->
<!-- ignored`. We also haven’t filtered the tests being run, so the end of the -->
<!-- summary shows `0 filtered out`. We’ll talk about ignoring and filtering out -->
<!-- tests in the next section, “Controlling How Tests Are Run.” -->

無視すると指定したテストは何もなかったため、まとめは`0 ignored`と示しています。
また、実行するテストにフィルタをかけもしなかったので、まとめの最後に`0 filtered out`と表示されています。
テストを無視することとフィルタすることに関しては次の節、「テストの実行され方を制御する」で語ります。

<!-- The `0 measured` statistic is for benchmark tests that measure performance. -->
<!-- Benchmark tests are, as of this writing, only available in nightly Rust. See -->
<!-- [the documentation about benchmark tests][bench] to learn more. -->

`0 measured`という統計は、パフォーマンスを測定するベンチマークテスト用です。
ベンチマークテストは、本書記述の時点では、ナイトリ版のRustでのみ利用可能です。
詳しくは、[ベンチマークテストのドキュメンテーション][bench]を参照されたし。

[bench]: ../../unstable-book/library-features/test.html

<!-- The next part of the test output, which starts with `Doc-tests adder`, is for -->
<!-- the results of any documentation tests. We don’t have any documentation tests -->
<!-- yet, but Rust can compile any code examples that appear in our API -->
<!-- documentation. This feature helps us keep our docs and our code in sync! We’ll -->
<!-- discuss how to write documentation tests in the “Documentation Comments As -->
<!-- Tests” section of Chapter 14. For now, we’ll ignore the `Doc-tests` output. -->

テスト出力の次の部分、つまり`Doc-tests adder`で始まる部分は、ドキュメンテーションテストの結果用のものです。
まだドキュメンテーションテストは何もないものの、コンパイラは、APIドキュメントに現れたどんなコード例もコンパイルできます。
この機能により、ドキュメントとコードを同期することができるわけです。ドキュメンテーションテストの書き方については、
第14章の「テストとしてのドキュメンテーションコメント」節で議論しましょう。今は、`Doc-tests`出力は無視します。

<!-- Let’s change the name of our test to see how that changes the test output. -->
<!-- Change the `it_works` function to a different name, such as `exploration`, like -->
<!-- so: -->

テストの名前を変更してどうテスト出力が変わるか確かめましょう。`it_works`関数を違う名前、`exploration`などに変えてください。
そう、以下のように:

<!-- <span class="filename">Filename: src/lib.rs</span> -->

<span class="filename">ファイル名: src/lib.rs</span>

```rust
# fn main() {}
#[cfg(test)]
mod tests {
    #[test]
    fn exploration() {
        assert_eq!(2 + 2, 4);
    }
}
```

<!-- Then run `cargo test` again. The output now shows `exploration` instead of -->
<!-- `it_works`: -->

そして、`cargo test`を再度走らせます。これで出力が`it_works`の代わりに`exploration`と表示しています:

```text
running 1 test
test tests::exploration ... ok

test result: ok. 1 passed; 0 failed; 0 ignored; 0 measured; 0 filtered out
```

<!-- Let’s add another test, but this time we’ll make a test that fails! Tests fail -->
<!-- when something in the test function panics. Each test is run in a new thread, -->
<!-- and when the main thread sees that a test thread has died, the test is marked -->
<!-- as failed. We talked about the simplest way to cause a panic in Chapter 9, -->
<!-- which is to call the `panic!` macro. Enter the new test, `another`, so your -->
<!-- *src/lib.rs* file looks like Listing 11-3. -->

別のテストを追加しますが、今回は失敗するテストにしましょう！テスト関数内の何かがパニックすると、
テストは失敗します。各テストは、新規スレッドで実行され、メインスレッドが、テストスレッドが死んだと確認した時、
テストは失敗と印づけられます。第9章でパニックを引き起こす最も単純な方法について語りました。
要するに、`panic!`マクロを呼び出すことです。*src/lib.rs*ファイルがリスト11-3のような見た目になるよう、
新しいテスト`another`を入力してください。

<!-- <span class="filename">Filename: src/lib.rs</span> -->

<span class="filename">ファイル名: src/lib.rs</span>

```rust
# fn main() {}
#[cfg(test)]
mod tests {
    #[test]
    fn exploration() {
        assert_eq!(2 + 2, 4);
    }

    #[test]
    fn another() {
        //このテストを失敗させる
        panic!("Make this test fail");
    }
}
```

<!-- <span class="caption">Listing 11-3: Adding a second test that will fail because -->
<!-- we call the `panic!` macro</span> -->

<span class="caption">リスト11-3: `panic!`マクロを呼び出したために失敗する2番目のテストを追加する</span>

<!-- Run the tests again using `cargo test`. The output should look like Listing -->
<!-- 11-4, which shows that our `exploration` test passed and `another` failed. -->

`cargo test`で再度テストを走らせてください。出力はリスト11-4のようになるはずであり、
`exploration`テストは通り、`another`は失敗したと表示されます。

```text
running 2 tests
test tests::exploration ... ok
test tests::another ... FAILED

failures:

---- tests::another stdout ----
    thread 'tests::another' panicked at 'Make this test fail', src/lib.rs:10:8
note: Run with `RUST_BACKTRACE=1` for a backtrace.

failures:
    tests::another

test result: FAILED. 1 passed; 1 failed; 0 ignored; 0 measured; 0 filtered out

error: test failed
```

<!-- <span class="caption">Listing 11-4: Test results when one test passes and one -->
<!-- test fails</span> -->

<span class="caption">リスト11-4: 一つのテストが通り、一つが失敗するときのテスト結果</span>

<!-- Instead of `ok`, the line `test tests::another` shows `FAILED`. Two new -->
<!-- sections appear between the individual results and the summary: the first -->
<!-- section displays the detailed reason for each test failure. In this case, -->
<!-- `another` failed because it `panicked at 'Make this test fail'`, which happened -->
<!-- on line 10 in the *src/lib.rs* file. The next section lists just the names of -->
<!-- all the failing tests, which is useful when there are lots of tests and lots of -->
<!-- detailed failing test output. We can use the name of a failing test to run just -->
<!-- that test to more easily debug it; we’ll talk more about ways to run tests in -->
<!-- the “Controlling How Tests Are Run” section. -->

`ok`の代わりに`test test::another`の行は、`FAILED`を表示しています。個々の結果とまとめの間に、
2つ新たな区域ができました: 最初の区域は、失敗したテスト各々の具体的な理由を表示しています。
今回の場合、`another`は`'Make this test fail'でパニックした`ために失敗し、
これは、*src/lib.rs*ファイルの10行で起きました。次の区域は失敗したテストの名前だけを列挙しています。
これは、テストがたくさんあり、失敗したテストの詳細がたくさん表示されるときに有用になります。
失敗したテストの名前を使用してそのテストだけを実行し、より簡単にデバッグすることができます。
テストの実行方法については、「テストの実行され方を制御する」節でもっと語りましょう。

<!-- The summary line displays at the end: overall, our test result is `FAILED`. -->
<!-- We had one test pass and one test fail. -->

サマリー行が最後に出力されています: 総合的に言うと、テスト結果は`失敗`でした。
一つのテストが通り、一つが失敗したわけです。

<!-- Now that you’ve seen what the test results look like in different scenarios, -->
<!-- let’s look at some macros other than `panic!` that are useful in tests. -->

異なる筋書きでのテスト結果がどんな風になるか見てきたので、テストを行う際に有用になる`panic!`以外のマクロに目を向けましょう。

<!-- ### Checking Results with the `assert!` Macro -->

### `assert!`マクロで結果を確認する

<!-- The `assert!` macro, provided by the standard library, is useful when you want -->
<!-- to ensure that some condition in a test evaluates to `true`. We give the -->
<!-- `assert!` macro an argument that evaluates to a Boolean. If the value is -->
<!-- `true`, `assert!` does nothing and the test passes. If the value is `false`, -->
<!-- the `assert!` macro calls the `panic!` macro, which causes the test to fail. -->
<!-- Using the `assert!` macro helps us check that our code is functioning in the -->
<!-- way we intend. -->

`assert!`マクロは、標準ライブラリで提供されていますが、テスト内の何らかの条件が`true`と評価されることを確かめたいときに有効です。
`assert!`マクロには、論理値に評価される引数を与えます。その値が`true`なら、
`assert!`は何もせず、テストは通ります。その値が`false`なら、`assert!`マクロは`panic!`マクロを呼び出し、
テストは失敗します。`assert!`マクロを使用することで、コードが意図した通りに機能していることを確認する助けになるわけです。

<!-- In Chapter 5, Listing 5-15, we used a `Rectangle` struct and a `can_hold` -->
<!-- method, which are repeated here in Listing 11-5. Let’s put this code in the -->
<!-- *src/lib.rs* file and write some tests for it using the `assert!` macro. -->

第5章のリスト5-15で、`Rectangle`構造体と`can_hold`メソッドを使用しました。リスト11-5でもそれを繰り返しています。
このコードを*src/lib.rs*ファイルに放り込み、`assert!`マクロでそれ用のテストを何か書いてみましょう。

<!-- <span class="filename">Filename: src/lib.rs</span> -->

<span class="filename">ファイル名: src/lib.rs</span>

```rust
# fn main() {}
#[derive(Debug)]
pub struct Rectangle {
    length: u32,
    width: u32,
}

impl Rectangle {
    pub fn can_hold(&self, other: &Rectangle) -> bool {
        self.length > other.length && self.width > other.width
    }
}
```

<!-- <span class="caption">Listing 11-5: Using the `Rectangle` struct and its -->
<!-- `can_hold` method from Chapter 5</span> -->

<span class="caption">リスト11-5: 第5章から`Rectangle`構造体とその`can_hold`メソッドを使用する</span>

<!-- The `can_hold` method returns a Boolean, which means it’s a perfect use case -->
<!-- for the `assert!` macro. In Listing 11-6, we write a test that exercises the -->
<!-- `can_hold` method by creating a `Rectangle` instance that has a length of 8 and -->
<!-- a width of 7 and asserting that it can hold another `Rectangle` instance that -->
<!-- has a length of 5 and a width of 1. -->

`can_hold`メソッドは論理値を返すので、`assert!`マクロの完璧なユースケースになるわけです。
リスト11-6で、長さが8、幅が7の`Rectangle`インスタンスを生成し、これが長さ5、
幅1の別の`Rectangle`インスタンスを保持できるとアサーションすることで`can_hold`を用いるテストを書きます。

<!-- <span class="filename">Filename: src/lib.rs</span> -->

<span class="filename">ファイル名: src/lib.rs</span>

```rust
# fn main() {}
#[cfg(test)]
mod tests {
    use super::*;

    #[test]
    fn larger_can_hold_smaller() {
        let larger = Rectangle { length: 8, width: 7 };
        let smaller = Rectangle { length: 5, width: 1 };

        assert!(larger.can_hold(&smaller));
    }
}
```

<!-- <span class="caption">Listing 11-6: A test for `can_hold` that checks whether a -->
<!-- larger rectangle can indeed hold a smaller rectangle</span> -->

<span class="caption">リスト11-6: より大きな四角形がより小さな四角形を確かに保持できるかを確認する`can_hold`用のテスト</span>

<!-- Note that we’ve added a new line inside the `tests` module: the `use super::*;`. -->
<!-- The `tests` module is a regular module that follows the usual visibility rules -->
<!-- we covered in Chapter 7 in the “Privacy Rules” section. Because the `tests` -->
<!-- module is an inner module, we need to bring the code under test in the outer -->
<!-- module into the scope of the inner module. We use a glob here so anything we -->
<!-- define in the outer module is available to this `tests` module. -->

`tests`モジュール内に新しい行を加えたことに注目してください: `use super::*`です。
`tests`モジュールは、第7章の「プライバシー規則」節で講義した通常の公開ルールに従う普通のモジュールです。
`tests`モジュールは、内部モジュールなので、外部モジュール内のテスト配下にあるコードを内部モジュールのスコープに持っていく必要があります。
ここではglobを使用して、外部モジュールで定義したもの全てがこの`tests`モジュールでも使用可能になるようにしています。

<!-- We’ve named our test `larger_can_hold_smaller`, and we’ve created the two -->
<!-- `Rectangle` instances that we need. Then we called the `assert!` macro and -->
<!-- passed it the result of calling `larger.can_hold(&smaller)`. This expression -->
<!-- is supposed to return `true`, so our test should pass. Let’s find out! -->

テストは`larger_can_hold_smaller`と名付け、必要な`Rectangle`インスタンスを2つ生成しています。
そして、`assert!`マクロを呼び出し、`larger.can_hold(&smaller)`の呼び出し結果を渡しました。
この式は、`true`を返すと考えられるので、テストは通るはずです。確かめましょう！

```text
running 1 test
test tests::larger_can_hold_smaller ... ok

test result: ok. 1 passed; 0 failed; 0 ignored; 0 measured; 0 filtered out
```

<!-- It does pass! Let’s add another test, this time asserting that a smaller -->
<!-- rectangle cannot hold a larger rectangle: -->

通ります！別のテストを追加しましょう。今回は、小さい四角形は、より大きな四角形を保持できないことをアサーションします。

<!-- <span class="filename">Filename: src/lib.rs</span> -->

<span class="filename">ファイル名: src/lib.rs</span>

```rust
# fn main() {}
#[cfg(test)]
mod tests {
    use super::*;

    #[test]
    fn larger_can_hold_smaller() {
        // --snip--
    }

    #[test]
    fn smaller_cannot_hold_larger() {
        let larger = Rectangle { length: 8, width: 7 };
        let smaller = Rectangle { length: 5, width: 1 };

        assert!(!smaller.can_hold(&larger));
    }
}
```

<!-- Because the correct result of the `can_hold` function in this case is `false`, -->
<!-- we need to negate that result before we pass it to the `assert!` macro. As a -->
<!-- result, our test will pass if `can_hold` returns `false`: -->

今回の場合、`can_hold`関数の正しい結果は`false`なので、その結果を`assert!`マクロに渡す前に反転させる必要があります。
結果として、`can_hold`が`false`を返せば、テストは通ります。

```text
running 2 tests
test tests::smaller_cannot_hold_larger ... ok
test tests::larger_can_hold_smaller ... ok

test result: ok. 2 passed; 0 failed; 0 ignored; 0 measured; 0 filtered out
```

<!-- Two tests that pass! Now let’s see what happens to our test results when we -->
<!-- introduce a bug in our code. Let’s change the implementation of the `can_hold` -->
<!-- method by replacing the greater than sign with a less than sign when it -->
<!-- compares the lengths: -->

通るテストが2つ！さて、コードにバグを導入したらテスト結果がどうなるか確認してみましょう。
長さを比較する大なり記号を小なり記号で置き換えて`can_hold`メソッドの実装を変更しましょう:

```rust
# fn main() {}
# #[derive(Debug)]
# pub struct Rectangle {
#     length: u32,
#     width: u32,
# }
// --snip--

impl Rectangle {
    pub fn can_hold(&self, other: &Rectangle) -> bool {
        self.length < other.length && self.width > other.width
    }
}
```

<!-- Running the tests now produces the following: -->

テストを実行すると、以下のような出力をします:

```text
running 2 tests
test tests::smaller_cannot_hold_larger ... ok
test tests::larger_can_hold_smaller ... FAILED

failures:

---- tests::larger_can_hold_smaller stdout ----
    thread 'tests::larger_can_hold_smaller' panicked at 'assertion failed:
    larger.can_hold(&smaller)', src/lib.rs:22:8
    (スレッド'tests::larger_can_hold_smallerはsrc/lib.rs:22:8の'assertion failed: larger.can_hold(&smaller)'
    でパニックしました)
note: Run with `RUST_BACKTRACE=1` for a backtrace.

failures:
    tests::larger_can_hold_smaller

test result: FAILED. 1 passed; 1 failed; 0 ignored; 0 measured; 0 filtered out
```

<!-- Our tests caught the bug! Because `larger.length` is 8 and `smaller.length` is -->
<!-- 5, the comparison of the lengths in `can_hold` now returns `false`: 8 is not -->
<!-- less than 5. -->

テストによりバグが捕捉されました！`larger.length`が8、`smaller.length`が5なので、
`can_hold`内の長さの比較が今は`false`を返すようになったのです: 8は5より小さくないですからね。

<!-- ### Testing Equality with the `assert_eq!` and `assert_ne!` Macros -->

### `assert_eq!`と`assert_ne!`マクロで等値性をテストする

<!-- A common way to test functionality is to compare the result of the code under -->
<!-- test to the value we expect the code to return to make sure they’re equal. We -->
<!-- could do this using the `assert!` macro and passing it an expression using the -->
<!-- `==` operator. However, this is such a common test that the standard library -->
<!-- provides a pair of macros—`assert_eq!` and `assert_ne!`—to perform this test -->
<!-- more conveniently. These macros compare two arguments for equality or -->
<!-- inequality, respectively. They’ll also print the two values if the assertion -->
<!-- fails, which makes it easier to see *why* the test failed; conversely, the -->
<!-- `assert!` macro only indicates that it got a `false` value for the `==` -->
<!-- expression, not the values that lead to the `false` value. -->

機能をテストする一般的な方法は、テスト下にあるコードの結果をコードが返すと期待される値と比較して、
等しいと確かめることです。これを`assert`マクロを使用して`==`演算子を使用した式を渡すことで行うこともできます。
しかしながら、これはありふれたテストなので、標準ライブラリには1組のマクロ(`assert_eq!`と`assert_ne!`)が提供され、
このテストをより便利に行うことができます。これらのマクロはそれぞれ、二つの引数を等値性と非等値性のために比較します。
また、アサーションが失敗したら二つの値の出力もし、テストが失敗した*原因*を確認しやすくなります。
一方で`assert!`マクロは、`==`式の値が`false`値になったことしか示唆せず、`false`値に導いた値は出力しません。

<!-- In Listing 11-7, we write a function named `add_two` that adds `2` to its -->
<!-- parameter and returns the result. Then we test this function using the -->
<!-- `assert_eq!` macro. -->

リスト11-7において、引数に`2`を加えて結果を返す`add_two`という名前の関数を書いています。
そして、`assert_eq!`マクロでこの関数をテストしています。

<!-- <span class="filename">Filename: src/lib.rs</span> -->

<span class="filename">ファイル名: src/lib.rs</span>

```rust
# fn main() {}
pub fn add_two(a: i32) -> i32 {
    a + 2
}

#[cfg(test)]
mod tests {
    use super::*;

    #[test]
    fn it_adds_two() {
        assert_eq!(4, add_two(2));
    }
}
```

<!-- <span class="caption">Listing 11-7: Testing the function `add_two` using the -->
<!-- `assert_eq!` macro</span> -->

<span class="caption">リスト11-7: `assert_eq!`マクロで`add_two`関数をテストする</span>

<!-- Let’s check that it passes! -->

テストが通ることを確認しましょう！

```text
running 1 test
test tests::it_adds_two ... ok

test result: ok. 1 passed; 0 failed; 0 ignored; 0 measured; 0 filtered out
```

<!-- The first argument we gave to the `assert_eq!` macro, `4`, is equal to the -->
<!-- result of calling `add_two(2)`. The line for this test is `test -->
<!-- tests::it_adds_two ... ok`, and the `ok` text indicates that our test passed! -->

`assert_eq!`マクロに与えた第1引数の`4`は、`add_two(2)`の呼び出し結果と等しいです。
このテストの行は`test tests::it_adds_two ... ok`であり、`ok`というテキストはテストが通ったことを示しています！

<!-- Let’s introduce a bug into our code to see what it looks like when a test that -->
<!-- uses `assert_eq!` fails. Change the implementation of the `add_two` function to -->
<!-- instead add `3`: -->

コードにバグを仕込んで、`assert_eq!`を使ったテストが失敗した時にどんな見た目になるのか確認してみましょう。
`add_two`関数の実装を代わりに`3`を足すように変えてください:

```rust
# fn main() {}
pub fn add_two(a: i32) -> i32 {
    a + 3
}
```

<!-- Run the tests again: -->

テストを再度実行します:

```text
running 1 test
test tests::it_adds_two ... FAILED

failures:

---- tests::it_adds_two stdout ----
        thread 'tests::it_adds_two' panicked at 'assertion failed: `(left == right)`
  left: `4`,
 right: `5`', src/lib.rs:11:8
note: Run with `RUST_BACKTRACE=1` for a backtrace.

failures:
    tests::it_adds_two

test result: FAILED. 0 passed; 1 failed; 0 ignored; 0 measured; 0 filtered out
```

<!-- Our test caught the bug! The `it_adds_two` test failed, displaying the message -->
<!-- `` assertion failed: `(left == right)` `` and showing that `left` was `4` and -->
<!-- `right` was `5`. This message is useful and helps us start debugging: it means -->
<!-- the `left` argument to `assert_eq!` was `4` but the `right` argument, where we -->
<!-- had `add_two(2)`, was `5`. -->

テストがバグを捕捉しました！`it_adds_two`のテストは失敗し、`` assertion failed: `(left == right)` ``というメッセージを表示し、
`left`は`4`で、`right`は`5`だったと示しています。このメッセージは有用で、デバッグを開始する助けになります:
`assert_eq!`の`left`引数は`4`だったが、`add_two(2)`がある`right`引数は`5`だったことを意味しています。

<!-- Note that in some languages and test frameworks, the parameters to the -->
<!-- functions that assert two values are equal are called `expected` and `actual`, -->
<!-- and the order in which we specify the arguments matters. However, in Rust, -->
<!-- they’re called `left` and `right`, and the order in which we specify the value -->
<!-- we expect and the value that the code under test produces doesn’t matter. We -->
<!-- could write the assertion in this test as `assert_eq!(add_two(2), 4)`, which -->
<!-- would result in a failure message that displays `` assertion failed: `(left == -->
<!-- right)` `` and that `left` was `5` and `right` was `4`. -->

二つの値が等しいとアサーションを行う関数の引数は、
`expected`と`actual`と呼ばれ、引数を指定する順序が問題になる言語やテストフレームワークもあることに注意してください。
ですがRustでは、`left`と`right`と呼ばれ、期待する値とテスト下のコードが生成する値を指定する順序は、
問題になりません。`assert_eq!(add_two(2), 4)`と今回のテストのアサーションを書くこともでき、
そうすると失敗メッセージは、`` assertion failed: `(left == right)` ``となり、
`left`が`5`で`right`が`4`と表示されるわけです。

<!-- The `assert_ne!` macro will pass if the two values we give it are not equal and -->
<!-- fail if they’re equal. This macro is most useful for cases when we’re not sure -->
<!-- what a value *will* be, but we know what the value definitely *won’t* be if our -->
<!-- code is functioning as we intend. For example, if we’re testing a function that -->
<!-- is guaranteed to change its input in some way, but the way in which the input -->
<!-- is changed depends on the day of the week that we run our tests, the best thing -->
<!-- to assert might be that the output of the function is not equal to the input. -->

`assert_ne!`マクロは、与えた2つの値が等しくなければ通り、等しければ失敗します。
このマクロは、値が何になる*だろう*か確信が持てないけれども、コードが意図した通りに動いていれば、
確実にこの値にはなら*ないだろう*とわかっているような場合に最も有用になります。例えば、
入力を何らかの手段で変えることが保障されているけれども、入力が変更される方法がテストを実行する曜日に依存する関数をテストしているなら、
アサーションすべき最善の事柄は、関数の出力が入力と等しくないことかもしれません。

<!-- Under the surface, the `assert_eq!` and `assert_ne!` macros use the operators -->
<!-- `==` and `!=`, respectively. When the assertions fail, these macros print their -->
<!-- arguments using debug formatting, which means the values being compared must -->
<!-- implement the `PartialEq` and `Debug` traits. All the primitive types and most -->
<!-- of the standard library types implement these traits. For structs and enums -->
<!-- that you define, you’ll need to implement `PartialEq` to assert that values of -->
<!-- those types are equal or not equal. You’ll need to implement `Debug` to print -->
<!-- out the values when the assertion fails. Because both traits are derivable traits, -->
<!-- as mentioned in Listing 5-12 in Chapter 5, this is usually as straightforward -->
<!-- as adding the `#[derive(PartialEq, Debug)]` annotation to your struct or enum -->
<!-- definition. See Appendix C for more details about these and other derivable -->
<!-- traits. -->

表面下では、`assert_eq!`と`assert_ne!`マクロはそれぞれ、`==`と`!=`演算子を使用しています。
アサーションが失敗すると、これらのマクロは引数をデバッグフォーマットを使用して出力するので、
比較対象の値は`PartialEq`と`Debug`トレイトを実装していなければなりません。
組み込み型の全部と、標準ライブラリの型はほぼ全てこれらのトレイトを実装しています。
自分で定義した構造体とenumについては、`PartialEq`を実装して、
その型の値が等しいか等しくないかアサーションする必要があるでしょう。`Debug`を実装して、
アサーションが失敗した時に値を出力する必要もあるでしょう。
第5章のリスト5-12で触れたように、どちらのトレイトも継承可能トレイトなので、
これは通常、構造体やenum定義に`#[derive(PartialEq, Debug)]`という注釈を追加するくらい単純になります。
これらや他の継承可能トレイトに関する詳細については、付録Cをご覧ください。

<!-- ### Adding Custom Failure Messages -->

### カスタムの失敗メッセージを追加する

<!-- We can also add a custom message to be printed with the failure message as -->
<!-- optional arguments to the `assert!`, `assert_eq!`, and `assert_ne!` macros. Any -->
<!-- arguments specified after the one required argument to `assert!` or the two -->
<!-- required arguments to `assert_eq!` and `assert_ne!` are passed along to the -->
<!-- `format!` macro (discussed in Chapter 8 in the “Concatenation with the `+` -->
<!-- Operator or the `format!` Macro” section), so you can pass a format string that -->
<!-- contains `{}` placeholders and values to go in those placeholders. Custom -->
<!-- messages are useful to document what an assertion means; when a test fails, -->
<!-- we’ll have a better idea of what the problem is with the code. -->

さらに、`assert!`、`assert_eq!`、`assert_ne!`の追加引数として、失敗メッセージと共にカスタムのメッセージが表示されるよう、
追加することもできます。`assert!`の1つの必須引数、
あるいは`assert_eq!`と`assert_ne!`の2つの必須引数の後に指定された引数はどれも`format!`マクロに明け渡されるので、
(format!マクロについては第8章の「`+`演算子または、`format!`マクロで連結する」節で議論しました)、
`{}`プレースホルダーを含むフォーマット文字列とこのプレースホルダーに置き換えられる値を渡すことができます。
カスタムメッセージは、アサーションがどんな意味を持つかドキュメント化するのに役に立ちます;
テストが失敗した時、問題が何なのかコードと共により良い考えを持てるでしょう。

<!-- For example, let’s say we have a function that greets people by name, and we -->
<!-- want to test that the name we pass into the function appears in the output: -->

例として、人々に名前で挨拶をする関数があり、関数に渡した名前が出力に出現することをテストしたいとしましょう:

<!-- <span class="filename">Filename: src/lib.rs</span> -->

<span class="filename">ファイル名: src/lib.rs</span>

```rust
# fn main() {}
pub fn greeting(name: &str) -> String {
    // こんにちは、{}さん！
    format!("Hello {}!", name)
}

#[cfg(test)]
mod tests {
    use super::*;

    #[test]
    fn greeting_contains_name() {
        let result = greeting("Carol");
        assert!(result.contains("Carol"));
    }
}
```

<!-- The requirements for this program haven’t been agreed upon yet, and we’re -->
<!-- pretty sure the `Hello` text at the beginning of the greeting will change. We -->
<!-- decided we don’t want to have to update the test when the requirements change, -->
<!-- so instead of checking for exact equality to the value returned from the -->
<!-- `greeting` function, we’ll just assert that the output contains the text of the -->
<!-- input parameter. -->

このプログラムの必要事項はまだ合意が得られておらず、挨拶の先頭の`Hello`というテキストは変わるだろうということは極めて確かです。
要件が変わった時にテストを更新しなくてもよいようにしたいと決定したので、
`greeting`関数から返る値と正確な等値性を確認するのではなく、出力が入力引数のテキストを含むことをアサーションするだけにします。

<!-- Let’s introduce a bug into this code by changing `greeting` to not include -->
<!-- `name` to see what this test failure looks like: -->

`greeting`が`name`を含まないように変更してこのコードにバグを仕込み、このテストの失敗がどんな見た目になるのか確かめましょう:

```rust
# fn main() {}
pub fn greeting(name: &str) -> String {
    String::from("Hello!")
}
```

<!-- Running this test produces the following: -->

このテストを実行すると、以下のように出力されます:

```text
running 1 test
test tests::greeting_contains_name ... FAILED

failures:

---- tests::greeting_contains_name stdout ----
        thread 'tests::greeting_contains_name' panicked at 'assertion failed:
result.contains("Carol")', src/lib.rs:12:8
note: Run with `RUST_BACKTRACE=1` for a backtrace.

failures:
    tests::greeting_contains_name
```

<!-- This result just indicates that the assertion failed and which line the -->
<!-- assertion is on. A more useful failure message in this case would print the -->
<!-- value we got from the `greeting` function. Let’s change the test function, -->
<!-- giving it a custom failure message made from a format string with a placeholder -->
<!-- filled in with the actual value we got from the `greeting` function: -->

この結果は、アサーションが失敗し、どの行にアサーションがあるかを示しているだけです。
より有用な失敗メッセージは今回の場合、`greeting`関数から得た値を出力することでしょう。
`greeting`関数から得た実際の値で埋められるプレースホルダーを含むフォーマット文字列からなるカスタムの失敗メッセージを与え、
テスト関数を変更しましょう:

```rust,ignore
#[test]
fn greeting_contains_name() {
    let result = greeting("Carol");
    assert!(
        result.contains("Carol"),
        //挨拶は名前を含んでいません。値は`{}`でした
        "Greeting did not contain name, value was `{}`", result
    );
}
```

<!-- Now when we run the test, we’ll get a more informative error message: -->

これでテストを実行したら、より有益なエラーメッセージが得られるでしょう:

```text
---- tests::greeting_contains_name stdout ----
        thread 'tests::greeting_contains_name' panicked at 'Greeting did not
contain name, value was `Hello!`', src/lib.rs:12:8
note: Run with `RUST_BACKTRACE=1` for a backtrace.
```

<!-- We can see the value we actually got in the test output, which would help us -->
<!-- debug what happened instead of what we were expecting to happen. -->

実際に得られた値がテスト出力に見られ、起こると想定していたものではなく、
起こったものをデバッグするのに役に立ちます。

<!-- ### Checking for Panics with `should_panic` -->

### `should_panic`でパニックを確認する

<!-- In addition to checking that our code returns the correct values we expect, -->
<!-- it’s also important to check that our code handles error conditions as we -->
<!-- expect. For example, consider the `Guess` type that we created in Chapter 9, -->
<!-- Listing 9-9. Other code that uses `Guess` depends on the guarantee that `Guess` -->
<!-- instances will only contain values between 1 and 100. We can write a test that -->
<!-- ensures that attempting to create a `Guess` instance with a value outside that -->
<!-- range panics. -->

期待する正しい値をコードが返すことを確認することに加えて、想定通りにコードがエラー状態を扱っていることを確認するのも重要です。
例えば、第9章のリスト9-9で生成した`Guess`型を考えてください。`Guess`を使用する他のコードは、
`Guess`のインスタンスは1から100の範囲の値しか含まないという保証に依存しています。
その範囲外の値で`Guess`インスタンスを生成しようとするとパニックすることを確認するテストを書くことができます。

<!-- We do this by adding another attribute, `should_panic`, to our test function. -->
<!-- This attribute makes a test pass if the code inside the function panics; the -->
<!-- test will fail if the code inside the function doesn’t panic. -->

これは、テスト関数に`should_panic`という別の属性を追加することで達成できます。
この属性は、関数内のコードがパニックしたら、テストを通過させます。つまり、
関数内のコードがパニックしなかったら、テストは失敗するわけです。

<!-- Listing 11-8 shows a test that checks that the error conditions of `Guess::new` -->
<!-- happen when we expect them to. -->

リスト11-8は、予想した時に`Guess::new`のエラー条件が発生していることを確認するテストを示しています。

<!-- <span class="filename">Filename: src/lib.rs</span> -->

<span class="filename">ファイル名: src/lib.rs</span>

```rust
# fn main() {}
pub struct Guess {
    value: u32,
}

impl Guess {
    pub fn new(value: u32) -> Guess {
        if value < 1 || value > 100 {
            //予想値は1から100の間でなければなりません
            panic!("Guess value must be between 1 and 100, got {}.", value);
        }

        Guess {
            value
        }
    }
}

#[cfg(test)]
mod tests {
    use super::*;

    #[test]
    #[should_panic]
    fn greater_than_100() {
        Guess::new(200);
    }
}
```

<!-- <span class="caption">Listing 11-8: Testing that a condition will cause a -->
<!-- `panic!`</span> -->

<span class="caption">リスト11-8: 状況が`panic!`を引き起こすとテストする</span>

<!-- We place the `#[should_panic]` attribute after the `#[test]` attribute and -->
<!-- before the test function it applies to. Let’s look at the result when this test -->
<!-- passes: -->

`#[test]`属性の後、適用するテスト関数の前に`#[should_panic]`属性を配置しています。
このテストが通るときの結果を見ましょう:

```text
running 1 test
test tests::greater_than_100 ... ok

test result: ok. 1 passed; 0 failed; 0 ignored; 0 measured; 0 filtered out
```

<!-- Looks good! Now let’s introduce a bug in our code by removing the condition -->
<!-- that the `new` function will panic if the value is greater than 100: -->

よさそうですね！では、値が100より大きいときに`new`関数がパニックするという条件を除去することでコードにバグを導入しましょう:

```rust
# fn main() {}
# pub struct Guess {
#     value: u32,
# }
#
// --snip--

impl Guess {
    pub fn new(value: u32) -> Guess {
        if value < 1  {
            panic!("Guess value must be between 1 and 100, got {}.", value);
        }

        Guess {
            value
        }
    }
}
```

<!-- When we run the test in Listing 11-8, it will fail: -->

リスト11-8のテストを実行すると、失敗するでしょう:

```text
running 1 test
test tests::greater_than_100 ... FAILED

failures:

failures:
    tests::greater_than_100

test result: FAILED. 0 passed; 1 failed; 0 ignored; 0 measured; 0 filtered out
```

<!-- We don’t get a very helpful message in this case, but when we look at the test -->
<!-- function, we see that it’s annotated with `#[should_panic]`. The failure we got -->
<!-- means that the code in the test function did not cause a panic. -->

この場合、それほど役に立つメッセージは得られませんが、テスト関数に目を向ければ、
`#[should_panic]`で注釈されていることがわかります。得られた失敗は、
テスト関数のコードがパニックを引き起こさなかったことを意味するのです。

<!-- Tests that use `should_panic` can be imprecise because they only indicate that -->
<!-- the code has caused some panic. A `should_panic` test would pass even if the -->
<!-- test panics for a different reason than the one we were expecting to happen. To -->
<!-- make `should_panic` tests more precise, we can add an optional `expected` -->
<!-- parameter to the `should_panic` attribute. The test harness will make sure that -->
<!-- the failure message contains the provided text. For example, consider the -->
<!-- modified code for `Guess` in Listing 11-9 where the `new` function panics with -->
<!-- different messages depending on whether the value is too small or too large. -->

`should_panic`を使用するテストは不正確なこともあります。なぜなら、コードが何らかのパニックを起こしたことしか示さないからです。
`should_panic`のテストは、起きると想定していたもの以外の理由でテストがパニックしても通ってしまうのです。
`should_panic`のテストの正確を期すために、`should_panic`属性の省略可能な`expected`引数を追加できます。
このテストの拘束具が、失敗メッセージに与えられたテキストが含まれていることを確かめてくれるでしょう。
例えば、リスト11-9の`Guess`の変更されたコードを考えてください。ここでは、
`new`関数は、値の大小によって異なるメッセージでパニックします。

<!-- <span class="filename">Filename: src/lib.rs</span> -->

<span class="filename">ファイル名: src/lib.rs</span>

```rust
# fn main() {}
# pub struct Guess {
#     value: u32,
# }
#
// --snip--

impl Guess {
    pub fn new(value: u32) -> Guess {
        if value < 1 {
            //予想値は、1以上でなければなりませんが、{}でした
            panic!("Guess value must be greater than or equal to 1, got {}.",
                   value);
        } else if value > 100 {
            //予想値は100以下でなければなりませんが、{}でした
            panic!("Guess value must be less than or equal to 100, got {}.",
                   value);
        }

        Guess {
            value
        }
    }
}

#[cfg(test)]
mod tests {
    use super::*;

    #[test]
    // 予想値は100以下でなければなりません
    #[should_panic(expected = "Guess value must be less than or equal to 100")]
    fn greater_than_100() {
        Guess::new(200);
    }
}
```

<!-- <span class="caption">Listing 11-9: Testing that a condition will cause a -->
<!-- `panic!` with a particular panic message</span> -->

<span class="caption">リスト11-9: 状況が特定のパニックメッセージで`panic!`を引き起こすことをテストする</span>

<!-- This test will pass because the value we put in the `should_panic` attribute’s -->
<!-- `expected` parameter is a substring of the message that the `Guess::new` -->
<!-- function panics with. We could have specified the entire panic message that we -->
<!-- expect, which in this case would be `Guess value must be less than or equal to -->
<!-- 100, got 200.` What you choose to specify in the expected parameter for -->
<!-- `should_panic` depends on how much of the panic message is unique or dynamic -->
<!-- and how precise you want your test to be. In this case, a substring of the -->
<!-- panic message is enough to ensure that the code in the test function executes -->
<!-- the `else if value > 100` case. -->

`should_panic`属性の`expected`引数に置いた値が`Guess::new`関数がパニックしたメッセージの一部になっているので、
このテストは通ります。予想されるパニックメッセージ全体を指定することもでき、今回の場合、
`Guess value must be less than or equal to 100, got 200.`となります。
`should_panic`の予想される引数に指定すると決めたものは、パニックメッセージの固有性や活動性、
テストの正確性によります。今回の場合、パニックメッセージの一部でも、テスト関数内のコードが、
`else if value > 100`ケースを実行していると確認するのに事足りるのです。

<!-- To see what happens when a `should_panic` test with an `expected` message -->
<!-- fails, let’s again introduce a bug into our code by swapping the bodies of the -->
<!-- `if value < 1` and the `else if value > 100` blocks: -->

`expected`メッセージありの`should_panic`テストが失敗すると何が起きるのが確かめるために、
`if value < 1`と`else if value > 100`ブロックの本体を入れ替えることで再度コードにバグを仕込みましょう:

```rust,ignore
if value < 1 {
    panic!("Guess value must be less than or equal to 100, got {}.", value);
} else if value > 100 {
    panic!("Guess value must be greater than or equal to 1, got {}.", value);
}
```

<!-- This time when we run the `should_panic` test, it will fail: -->

`should_panic`テストを実行すると、今回は失敗するでしょう:

```text
running 1 test
test tests::greater_than_100 ... FAILED

failures:

---- tests::greater_than_100 stdout ----
        thread 'tests::greater_than_100' panicked at 'Guess value must be
greater than or equal to 1, got 200.', src/lib.rs:11:12
note: Run with `RUST_BACKTRACE=1` for a backtrace.
note: Panic did not include expected string 'Guess value must be less than or
equal to 100'
(注釈: パニックには'Guess value must be less than or equal to 100'という予想される文字列が含まれませんでした)

failures:
    tests::greater_than_100

test result: FAILED. 0 passed; 1 failed; 0 ignored; 0 measured; 0 filtered out
```

<!-- The failure message indicates that this test did indeed panic as we expected, -->
<!-- but the panic message did not include the expected string `'Guess value must be -->
<!-- less than or equal to 100'`. The panic message that we did get in this case was -->
<!-- `Guess value must be greater than or equal to 1, got 200.` Now we can start -->
<!-- figuring out where our bug is! -->

この失敗メッセージは、このテストが確かにまさしく予想通りパニックしたことを示唆していますが、
パニックメッセージは、予想される文字列の`'Guess value must be less than or equal to 100'`を含んでいませんでした。
実際に得られたパニックメッセージは今回の場合、`Guess value must be greater than or equal to 1, got 200`でした。
そうしてバグの所在地を割り出し始めることができるわけです！

<!-- Now that you know several ways to write tests, let’s look at what is happening -->
<!-- when we run our tests and explore the different options we can use with `cargo -->
<!-- test`. -->

今やテスト記法を複数知ったので、テストを走らせる際に起きていることに目を向け、
`cargo test`で使用できるいろんなオプションを探究しましょう。
